{
 "cells": [
  {
   "cell_type": "code",
   "execution_count": 1,
   "metadata": {},
   "outputs": [
    {
     "name": "stderr",
     "output_type": "stream",
     "text": [
      "sh: line 3: cd: /home/ec2-user/SageMaker/donkey/sagetrain/container: No such file or directory\n"
     ]
    }
   ],
   "source": [
    "%%sh\n",
    "\n",
    "image=robocarkr\n",
    "cd /home/ec2-user/SageMaker/donkey/sagetrain/container\n",
    "\n",
    "\n"
   ]
  },
  {
   "cell_type": "code",
   "execution_count": null,
   "metadata": {},
   "outputs": [],
   "source": [
    "\n"
   ]
  },
  {
   "cell_type": "code",
   "execution_count": 4,
   "metadata": {},
   "outputs": [
    {
     "name": "stderr",
     "output_type": "stream",
     "text": [
      "INFO:sagemaker:Creating training-job with name: robocar-yikster-2018-10-08-06-37-53-712\n"
     ]
    },
    {
     "name": "stdout",
     "output_type": "stream",
     "text": [
      "2018-10-08 06:37:54 Starting - Starting the training job...\n",
      "Launching requested ML instances......\n",
      "Preparing the instances for training...\n",
      "2018-10-08 06:39:42 Downloading - Downloading input data...\n",
      "2018-10-08 06:40:24 Training - Downloading the training image...\n",
      "Training image download completed. Training in progress..\n",
      "\u001b[31m/usr/local/lib/python3.5/dist-packages/h5py/__init__.py:36: FutureWarning: Conversion of the second argument of issubdtype from `float` to `np.floating` is deprecated. In future, it will be treated as `np.float64 == np.dtype(float).type`.\n",
      "  from ._conv import register_converters as _register_converters\u001b[0m\n",
      "\u001b[31mUsing TensorFlow backend.\u001b[0m\n",
      "\u001b[31mStarting the training.\u001b[0m\n",
      "\u001b[31mTubGroup:tubpaths: ['/opt/ml/input/data/training']\u001b[0m\n",
      "\u001b[31mpath_in_tub: /opt/ml/input/data/training\u001b[0m\n",
      "\u001b[31mTub exists: /opt/ml/input/data/training\u001b[0m\n",
      "\u001b[31mjoining the tubs 2736 records together. This could take 0 minutes.\u001b[0m\n",
      "\u001b[31mEpoch 1/20\u001b[0m\n",
      "\u001b[31mException during training: [Errno 2] No such file or directory: '/opt/ml/input/data/training/6821_cam-image_array_.jpg'\u001b[0m\n",
      "\u001b[31mTraceback (most recent call last):\n",
      "  File \"/opt/program/train\", line 648, in train\n",
      "    validation_steps=steps_per_epoch*(1.0 - TRAINING_SPLIT))\n",
      "  File \"/usr/local/lib/python3.5/dist-packages/keras/legacy/interfaces.py\", line 91, in wrapper\n",
      "    return func(*args, **kwargs)\n",
      "  File \"/usr/local/lib/python3.5/dist-packages/keras/engine/training.py\", line 2192, in fit_generator\n",
      "    generator_output = next(output_generator)\n",
      "  File \"/usr/local/lib/python3.5/dist-packages/keras/utils/data_utils.py\", line 793, in get\n",
      "    six.reraise(value.__class__, value, value.__traceback__)\n",
      "  File \"/usr/local/lib/python3.5/dist-packages/six.py\", line 693, in reraise\n",
      "    raise value\n",
      "  File \"/usr/local/lib/python3.5/dist-packages/keras/utils/data_utils.py\", line 658, in _data_generator_task\n",
      "    generator_output = next(self._generator)\n",
      "  File \"/opt/program/train\", line 337, in get_train_gen\n",
      "    batch = next(batch_gen)\n",
      "  File \"/opt/program/train\", line 319, in get_batch_gen\n",
      "    record_list.append(next(record_gen))\n",
      "  File \"/opt/program/train\", line 304, in get_record_gen\n",
      "    record_dict = self.read_record(record_dict)\n",
      "  File \"/opt/program/train\", line 267, in read_record\n",
      "    img = Image.open((val))\n",
      "  File \"/usr/local/lib/python3.5/dist-packages/PIL/Image.py\", line 2548, in open\n",
      "    fp = builtins.open(filename, \"rb\")\u001b[0m\n",
      "\u001b[31mFileNotFoundError: [Errno 2] No such file or directory: '/opt/ml/input/data/training/6821_cam-image_array_.jpg'\n",
      "\u001b[0m\n",
      "\n",
      "2018-10-08 06:41:00 Uploading - Uploading generated training model\n",
      "2018-10-08 06:41:06 Failed - Training job failed\n"
     ]
    },
    {
     "ename": "ValueError",
     "evalue": "Error training robocar-yikster-2018-10-08-06-37-53-712: Failed Reason: AlgorithmError: Exception during training: [Errno 2] No such file or directory: '/opt/ml/input/data/training/6821_cam-image_array_.jpg'\nTraceback (most recent call last):\n  File \"/opt/program/train\", line 648, in train\n    validation_steps=steps_per_epoch*(1.0 - TRAINING_SPLIT))\n  File \"/usr/local/lib/python3.5/dist-packages/keras/legacy/interfaces.py\", line 91, in wrapper\n    return func(*args, **kwargs)\n  File \"/usr/local/lib/python3.5/dist-packages/keras/engine/training.py\", line 2192, in fit_generator\n    generator_output = next(output_generator)\n  File \"/usr/local/lib/python3.5/dist-packages/keras/utils/data_utils.py\", line 793, in get\n    six.reraise(value.__class__, value, value.__traceback__)\n  File \"/usr/local/lib/python3.5/dist-packages/six.py\", line 693, in reraise\n    raise value\n  File \"/usr/local/lib/python3.5/dist-packages/keras/utils/data_utils.py\", line 658, in _data_generator_task\n    generator_output = next(self._generator)\n  File \"/opt/program/train\", line 337, in get_train_gen\n    batch =",
     "output_type": "error",
     "traceback": [
      "\u001b[0;31m---------------------------------------------------------------------------\u001b[0m",
      "\u001b[0;31mValueError\u001b[0m                                Traceback (most recent call last)",
      "\u001b[0;32m<ipython-input-4-fc9c7db8679d>\u001b[0m in \u001b[0;36m<module>\u001b[0;34m()\u001b[0m\n\u001b[1;32m     16\u001b[0m                        sagemaker_session=sagemaker_session)\n\u001b[1;32m     17\u001b[0m \u001b[0;34m\u001b[0m\u001b[0m\n\u001b[0;32m---> 18\u001b[0;31m \u001b[0malgo\u001b[0m\u001b[0;34m.\u001b[0m\u001b[0mfit\u001b[0m\u001b[0;34m(\u001b[0m\u001b[0minputs\u001b[0m\u001b[0;34m)\u001b[0m\u001b[0;34m\u001b[0m\u001b[0m\n\u001b[0m",
      "\u001b[0;32m~/anaconda3/envs/tensorflow_p36/lib/python3.6/site-packages/sagemaker/estimator.py\u001b[0m in \u001b[0;36mfit\u001b[0;34m(self, inputs, wait, logs, job_name)\u001b[0m\n\u001b[1;32m    191\u001b[0m         \u001b[0mself\u001b[0m\u001b[0;34m.\u001b[0m\u001b[0mlatest_training_job\u001b[0m \u001b[0;34m=\u001b[0m \u001b[0m_TrainingJob\u001b[0m\u001b[0;34m.\u001b[0m\u001b[0mstart_new\u001b[0m\u001b[0;34m(\u001b[0m\u001b[0mself\u001b[0m\u001b[0;34m,\u001b[0m \u001b[0minputs\u001b[0m\u001b[0;34m)\u001b[0m\u001b[0;34m\u001b[0m\u001b[0m\n\u001b[1;32m    192\u001b[0m         \u001b[0;32mif\u001b[0m \u001b[0mwait\u001b[0m\u001b[0;34m:\u001b[0m\u001b[0;34m\u001b[0m\u001b[0m\n\u001b[0;32m--> 193\u001b[0;31m             \u001b[0mself\u001b[0m\u001b[0;34m.\u001b[0m\u001b[0mlatest_training_job\u001b[0m\u001b[0;34m.\u001b[0m\u001b[0mwait\u001b[0m\u001b[0;34m(\u001b[0m\u001b[0mlogs\u001b[0m\u001b[0;34m=\u001b[0m\u001b[0mlogs\u001b[0m\u001b[0;34m)\u001b[0m\u001b[0;34m\u001b[0m\u001b[0m\n\u001b[0m\u001b[1;32m    194\u001b[0m \u001b[0;34m\u001b[0m\u001b[0m\n\u001b[1;32m    195\u001b[0m     \u001b[0;34m@\u001b[0m\u001b[0mclassmethod\u001b[0m\u001b[0;34m\u001b[0m\u001b[0m\n",
      "\u001b[0;32m~/anaconda3/envs/tensorflow_p36/lib/python3.6/site-packages/sagemaker/estimator.py\u001b[0m in \u001b[0;36mwait\u001b[0;34m(self, logs)\u001b[0m\n\u001b[1;32m    421\u001b[0m     \u001b[0;32mdef\u001b[0m \u001b[0mwait\u001b[0m\u001b[0;34m(\u001b[0m\u001b[0mself\u001b[0m\u001b[0;34m,\u001b[0m \u001b[0mlogs\u001b[0m\u001b[0;34m=\u001b[0m\u001b[0;32mTrue\u001b[0m\u001b[0;34m)\u001b[0m\u001b[0;34m:\u001b[0m\u001b[0;34m\u001b[0m\u001b[0m\n\u001b[1;32m    422\u001b[0m         \u001b[0;32mif\u001b[0m \u001b[0mlogs\u001b[0m\u001b[0;34m:\u001b[0m\u001b[0;34m\u001b[0m\u001b[0m\n\u001b[0;32m--> 423\u001b[0;31m             \u001b[0mself\u001b[0m\u001b[0;34m.\u001b[0m\u001b[0msagemaker_session\u001b[0m\u001b[0;34m.\u001b[0m\u001b[0mlogs_for_job\u001b[0m\u001b[0;34m(\u001b[0m\u001b[0mself\u001b[0m\u001b[0;34m.\u001b[0m\u001b[0mjob_name\u001b[0m\u001b[0;34m,\u001b[0m \u001b[0mwait\u001b[0m\u001b[0;34m=\u001b[0m\u001b[0;32mTrue\u001b[0m\u001b[0;34m)\u001b[0m\u001b[0;34m\u001b[0m\u001b[0m\n\u001b[0m\u001b[1;32m    424\u001b[0m         \u001b[0;32melse\u001b[0m\u001b[0;34m:\u001b[0m\u001b[0;34m\u001b[0m\u001b[0m\n\u001b[1;32m    425\u001b[0m             \u001b[0mself\u001b[0m\u001b[0;34m.\u001b[0m\u001b[0msagemaker_session\u001b[0m\u001b[0;34m.\u001b[0m\u001b[0mwait_for_job\u001b[0m\u001b[0;34m(\u001b[0m\u001b[0mself\u001b[0m\u001b[0;34m.\u001b[0m\u001b[0mjob_name\u001b[0m\u001b[0;34m)\u001b[0m\u001b[0;34m\u001b[0m\u001b[0m\n",
      "\u001b[0;32m~/anaconda3/envs/tensorflow_p36/lib/python3.6/site-packages/sagemaker/session.py\u001b[0m in \u001b[0;36mlogs_for_job\u001b[0;34m(self, job_name, wait, poll)\u001b[0m\n\u001b[1;32m    907\u001b[0m \u001b[0;34m\u001b[0m\u001b[0m\n\u001b[1;32m    908\u001b[0m         \u001b[0;32mif\u001b[0m \u001b[0mwait\u001b[0m\u001b[0;34m:\u001b[0m\u001b[0;34m\u001b[0m\u001b[0m\n\u001b[0;32m--> 909\u001b[0;31m             \u001b[0mself\u001b[0m\u001b[0;34m.\u001b[0m\u001b[0m_check_job_status\u001b[0m\u001b[0;34m(\u001b[0m\u001b[0mjob_name\u001b[0m\u001b[0;34m,\u001b[0m \u001b[0mdescription\u001b[0m\u001b[0;34m,\u001b[0m \u001b[0;34m'TrainingJobStatus'\u001b[0m\u001b[0;34m)\u001b[0m\u001b[0;34m\u001b[0m\u001b[0m\n\u001b[0m\u001b[1;32m    910\u001b[0m             \u001b[0;32mif\u001b[0m \u001b[0mdot\u001b[0m\u001b[0;34m:\u001b[0m\u001b[0;34m\u001b[0m\u001b[0m\n\u001b[1;32m    911\u001b[0m                 \u001b[0mprint\u001b[0m\u001b[0;34m(\u001b[0m\u001b[0;34m)\u001b[0m\u001b[0;34m\u001b[0m\u001b[0m\n",
      "\u001b[0;32m~/anaconda3/envs/tensorflow_p36/lib/python3.6/site-packages/sagemaker/session.py\u001b[0m in \u001b[0;36m_check_job_status\u001b[0;34m(self, job, desc, status_key_name)\u001b[0m\n\u001b[1;32m    626\u001b[0m         \u001b[0;32mif\u001b[0m \u001b[0mstatus\u001b[0m \u001b[0;34m!=\u001b[0m \u001b[0;34m'Completed'\u001b[0m \u001b[0;32mand\u001b[0m \u001b[0mstatus\u001b[0m \u001b[0;34m!=\u001b[0m \u001b[0;34m'Stopped'\u001b[0m\u001b[0;34m:\u001b[0m\u001b[0;34m\u001b[0m\u001b[0m\n\u001b[1;32m    627\u001b[0m             \u001b[0mreason\u001b[0m \u001b[0;34m=\u001b[0m \u001b[0mdesc\u001b[0m\u001b[0;34m.\u001b[0m\u001b[0mget\u001b[0m\u001b[0;34m(\u001b[0m\u001b[0;34m'FailureReason'\u001b[0m\u001b[0;34m,\u001b[0m \u001b[0;34m'(No reason provided)'\u001b[0m\u001b[0;34m)\u001b[0m\u001b[0;34m\u001b[0m\u001b[0m\n\u001b[0;32m--> 628\u001b[0;31m             \u001b[0;32mraise\u001b[0m \u001b[0mValueError\u001b[0m\u001b[0;34m(\u001b[0m\u001b[0;34m'Error training {}: {} Reason: {}'\u001b[0m\u001b[0;34m.\u001b[0m\u001b[0mformat\u001b[0m\u001b[0;34m(\u001b[0m\u001b[0mjob\u001b[0m\u001b[0;34m,\u001b[0m \u001b[0mstatus\u001b[0m\u001b[0;34m,\u001b[0m \u001b[0mreason\u001b[0m\u001b[0;34m)\u001b[0m\u001b[0;34m)\u001b[0m\u001b[0;34m\u001b[0m\u001b[0m\n\u001b[0m\u001b[1;32m    629\u001b[0m \u001b[0;34m\u001b[0m\u001b[0m\n\u001b[1;32m    630\u001b[0m     \u001b[0;32mdef\u001b[0m \u001b[0mwait_for_endpoint\u001b[0m\u001b[0;34m(\u001b[0m\u001b[0mself\u001b[0m\u001b[0;34m,\u001b[0m \u001b[0mendpoint\u001b[0m\u001b[0;34m,\u001b[0m \u001b[0mpoll\u001b[0m\u001b[0;34m=\u001b[0m\u001b[0;36m5\u001b[0m\u001b[0;34m)\u001b[0m\u001b[0;34m:\u001b[0m\u001b[0;34m\u001b[0m\u001b[0m\n",
      "\u001b[0;31mValueError\u001b[0m: Error training robocar-yikster-2018-10-08-06-37-53-712: Failed Reason: AlgorithmError: Exception during training: [Errno 2] No such file or directory: '/opt/ml/input/data/training/6821_cam-image_array_.jpg'\nTraceback (most recent call last):\n  File \"/opt/program/train\", line 648, in train\n    validation_steps=steps_per_epoch*(1.0 - TRAINING_SPLIT))\n  File \"/usr/local/lib/python3.5/dist-packages/keras/legacy/interfaces.py\", line 91, in wrapper\n    return func(*args, **kwargs)\n  File \"/usr/local/lib/python3.5/dist-packages/keras/engine/training.py\", line 2192, in fit_generator\n    generator_output = next(output_generator)\n  File \"/usr/local/lib/python3.5/dist-packages/keras/utils/data_utils.py\", line 793, in get\n    six.reraise(value.__class__, value, value.__traceback__)\n  File \"/usr/local/lib/python3.5/dist-packages/six.py\", line 693, in reraise\n    raise value\n  File \"/usr/local/lib/python3.5/dist-packages/keras/utils/data_utils.py\", line 658, in _data_generator_task\n    generator_output = next(self._generator)\n  File \"/opt/program/train\", line 337, in get_train_gen\n    batch ="
     ]
    }
   ],
   "source": [
    "import os\n",
    "import sagemaker as sage\n",
    "from sagemaker import get_execution_role\n",
    "\n",
    "sagemaker_session = sage.Session()\n",
    "\n",
    "role = get_execution_role()\n",
    "\n",
    "inputs = \"s3://kyoungsu-robocar-nrt/traindata/blue/20181008_070220\"\n",
    "#inputs = \"s3://kyoungsu-robocar-icn/tub-test\"\n",
    "output_bucket = \"kyoungsu-robocar-nrt\"\n",
    "image=\"125492839279.dkr.ecr.ap-northeast-1.amazonaws.com/robocar-yikster\"\n",
    "algo = sage.estimator.Estimator(image,\n",
    "                       role, 1, 'ml.p3.2xlarge', #train_instance_type='local', \n",
    "                       output_path=\"s3://{}/output\".format(output_bucket),\n",
    "                       sagemaker_session=sagemaker_session)\n",
    "\n",
    "algo.fit(inputs)\n"
   ]
  },
  {
   "cell_type": "code",
   "execution_count": null,
   "metadata": {},
   "outputs": [],
   "source": []
  },
  {
   "cell_type": "code",
   "execution_count": null,
   "metadata": {},
   "outputs": [],
   "source": []
  }
 ],
 "metadata": {
  "kernelspec": {
   "display_name": "conda_tensorflow_p36",
   "language": "python",
   "name": "conda_tensorflow_p36"
  },
  "language_info": {
   "codemirror_mode": {
    "name": "ipython",
    "version": 3
   },
   "file_extension": ".py",
   "mimetype": "text/x-python",
   "name": "python",
   "nbconvert_exporter": "python",
   "pygments_lexer": "ipython3",
   "version": "3.6.5"
  }
 },
 "nbformat": 4,
 "nbformat_minor": 2
}
